Workbook

Sheet README
A1: Agentic AI Risk Tiering Prototype – MVP Blueprint & Synthetic Data Pack
A2: Aligned to: EU AI Act (Reg. (EU) 2024/1689, as amended by the Digital Omnibus on AI, Reg. (EU) 2026/1744) · NIST AI RMF 1.0 (+ AI 600-1 GenAI Profile) · ISO/IEC 42001:2023
A4: Sheet guide
A5: Dashboard – live KPIs computed from the synthetic data (tier mix, agent vs SME agreement, gaps, remediation, monitoring, backlog effort)
A6: MVP_Roadmap – 4 MVPs: objective, scope, agents, acceptance criteria, KPIs, HITL design, risks, exit criteria
A7: MVP_Backlog – 39 user stories with priority, effort points, acceptance criteria, agent and framework reference
A8: Agent_Catalog – 13 agents: purpose, inputs/outputs, tools, autonomy, human checkpoints, guardrails, eval metrics
A9: Tiering_Rules – ordered decision logic (R1–R12) and Annex III domain guide used by the rules engine + LLM agents
A10: Tier_Obligations – internal tier definitions, SLAs, review depth, and EU tier obligations / application dates
A11: Framework_Map – 24-requirement crosswalk: EU AI Act ↔ NIST AI RMF ↔ ISO/IEC 42001, with tier applicability and evidence
A12: Config – editable parameters (as-of date, weights, thresholds, tier tables) that drive formulas
A13: Syn_AI_Inventory – 30 synthetic AI systems (fictional 'Northwind Financial Group') with intake flags [feeds Intake/Discovery agents]
... A29: • Tiering is an assessment aid; final classification accountability stays with named humans (AI Governance + Legal).

Sheet Dashboard
A1: AI Risk Tiering Prototype – Dashboard (synthetic data)
A2: ="As-of date: "&TEXT(Config!B4,"yyyy-mm-dd")&" | All figures computed from Syn_* sheets" -> As-of date: 2026-09-28 | All figures computed from Syn_* sheets
A4: Headline KPI | B4: Value | C4: Definition
A5: Total AI systems in inventory | B5: =COUNTA(Syn_AI_Inventory!$A$5:$A$34) -> 30 | C5: Rows in Syn_AI_Inventory
A6: Average intake completeness | B6: =AVERAGE(Syn_AI_Inventory!$AA$5:$AA$34) -> 0.90133333 | C6: MVP-1 KPI (target ≥95%)
A7: Systems validated as Prohibited (T0) | B7: =COUNTIF(Syn_Tiering!$J$5:$J$34,"Prohibited (Art.5)") -> 3 | C7: SME-validated EU tier
A8: Systems validated as High-Risk (Annex I + III) | B8: =COUNTIF(Syn_Tiering!$J$5:$J$34,"High-Risk*") -> 8 | C8: Wildcard on 'High-Risk*'
A9: Agent–SME agreement | B9: =COUNTIF(Syn_Tiering!$M$5:$M$34,"Yes")/COUNTA(Syn_Tiering!$A$5:$A$34) -> 0.9 | C9: MVP-2 target ≥90%
A10: Rules-engine–SME agreement | B10: =COUNTIF(Syn_Tiering!$N$5:$N$34,"Yes")/COUNTA(Syn_Tiering!$A$5:$A$34) -> 0.96666667 | C10: Rules alone miss hidden indicators
A11: Prohibited recall – rules engine only | B11: =IFERROR(COUNTIFS(Syn_Tiering!$J$5:$J$34,"Prohibited (Art.5)",Syn_Tiering!$C$5:$C$34,"Prohibited (Art.5)")/COUNTIF(Syn_Tiering!$J$5:$J$34,"Prohibited (Art.5)"),"n/a") -> 0.66666667 | C11: Share of SME-confirmed prohibited caught
A12: Prohibited recall – agent (LLM + rules) | B12: =IFERROR(COUNTIFS(Syn_Tiering!$J$5:$J$34,"Prohibited (Art.5)",Syn_Tiering!$G$5:$G$34,"Prohibited (Art.5)")/COUNTIF(Syn_Tiering!$J$5:$J$34,"Prohibited (Art.5)"),"n/a") -> 1 | C12: MVP-2 target 100%
A13: Average agent confidence | B13: =AVERAGE(Syn_Tiering!$H$5:$H$34) -> 0.87133333 | C13: Synthetic
A14: Fast-track review share | B14: =COUNTIF(Syn_Tiering!$P$5:$P$34,"Fast-track*")/COUNTA(Syn_Tiering!$A$5:$A$34) -> 0.46666667 | C14: Agent = rules, confidence ≥ threshold, not T1
A15: Average compliance score (gap assessment) | B15: =AVERAGE(Syn_Gap_Assessment!$N$5:$N$134) -> 0.56153846 | C15: Implemented = 1, Partial = Config weight, else 0
A16: Open remediation actions | B16: =COUNTA(Syn_Remediation!$A$5:$A$61)-COUNTIF(Syn_Remediation!$N$5:$N$61,"Closed") -> 45 | C16: Status ≠ Closed
A17: Overdue remediation actions | B17: =COUNTIF(Syn_Remediation!$O$5:$O$61,"Overdue") -> 18 | C17: Due date before as-of date
A18: Re-tier triggers from monitoring | B18: =COUNTIF(Syn_Monitoring!$K$5:$K$30,"Yes") -> 16 | C18: Material change or High/Critical severity
A19: Potential serious incidents (Art.73) | B19: =COUNTIF(Syn_Monitoring!$L$5:$L$30,"Yes") -> 3 | C19: T0/T1 systems with critical events
A21: 1. EU AI Act tier distribution
A22: EU AI Act Tier | B22: Rules Engine | C22: Agent Suggested | D22: SME Validated | E22: % of Inventory (validated)
A23: =Config!A17 -> Prohibited (Art.5) | B23: =COUNTIF(Syn_Tiering!$C$5:$C$34,A23) -> 2 | C23: =COUNTIF(Syn_Tiering!$G$5:$G$34,A23) -> 3 | D23: =COUNTIF(Syn_Tiering!$J$5:$J$34,A23) -> 3 | E23: =D23/COUNTA(Syn_Tiering!$A$5:$A$34) -> 0.1
A24: =Config!A18 -> High-Risk (Annex I) | B24: =COUNTIF(Syn_Tiering!$C$5:$C$34,A24) -> 0 | C24: =COUNTIF(Syn_Tiering!$G$5:$G$34,A24) -> 0 | D24: =COUNTIF(Syn_Tiering!$J$5:$J$34,A24) -> 0 | E24: =D24/COUNTA(Syn_Tiering!$A$5:$A$34) -> 0
A25: =Config!A19 -> High-Risk (Annex III) | B25: =COUNTIF(Syn_Tiering!$C$5:$C$34,A25) -> 9 | C25: =COUNTIF(Syn_Tiering!$G$5:$G$34,A25) -> 9 | D25: =COUNTIF(Syn_Tiering!$J$5:$J$34,A25) -> 8 | E25: =D25/COUNTA(Syn_Tiering!$A$5:$A$34) -> 0.26666667
A26: =Config!A20 -> GPAI with Systemic Risk | B26: =COUNTIF(Syn_Tiering!$C$5:$C$34,A26) -> 0 | C26: =COUNTIF(Syn_Tiering!$G$5:$G$34,A26) -> 0 | D26: =COUNTIF(Syn_Tiering!$J$5:$J$34,A26) -> 0 | E26: =D26/COUNTA(Syn_Tiering!$A$5:$A$34) -> 0
A27: =Config!A21 -> GPAI | B27: =COUNTIF(Syn_Tiering!$C$5:$C$34,A27) -> 1 | C27: =COUNTIF(Syn_Tiering!$G$5:$G$34,A27) -> 1 | D27: =COUNTIF(Syn_Tiering!$J$5:$J$34,A27) -> 1 | E27: =D27/COUNTA(Syn_Tiering!$A$5:$A$34) -> 0.033333333
A28: =Config!A22 -> Limited Risk (Art.50) | B28: =COUNTIF(Syn_Tiering!$C$5:$C$34,A28) -> 7 | C28: =COUNTIF(Syn_Tiering!$G$5:$G$34,A28) -> 7 | D28: =COUNTIF(Syn_Tiering!$J$5:$J$34,A28) -> 7 | E28: =D28/COUNTA(Syn_Tiering!$A$5:$A$34) -> 0.23333333
A29: =Config!A23 -> Minimal Risk | B29: =COUNTIF(Syn_Tiering!$C$5:$C$34,A29) -> 10 | C29: =COUNTIF(Syn_Tiering!$G$5:$G$34,A29) -> 9 | D29: =COUNTIF(Syn_Tiering!$J$5:$J$34,A29) -> 10 | E29: =D29/COUNTA(Syn_Tiering!$A$5:$A$34) -> 0.33333333
A30: =Config!A24 -> Out of EU AI Act Scope | B30: =COUNTIF(Syn_Tiering!$C$5:$C$34,A30) -> 1 | C30: =COUNTIF(Syn_Tiering!$G$5:$G$34,A30) -> 1 | D30: =COUNTIF(Syn_Tiering!$J$5:$J$34,A30) -> 1 | E30: =D30/COUNTA(Syn_Tiering!$A$5:$A$34) -> 0.033333333
A31: Total | B31: =SUM(B23:B30) -> 30 | C31: =SUM(C23:C30) -> 30 | D31: =SUM(D23:D30) -> 30
A33: 2. Final validated internal AI Risk tiers
A34: Internal Tier | B34: # Systems | C34: % of Inventory | D34: Remediation SLA (days) | E34: Priority
A35: =Config!B28 -> T0 - Stop | B35: =COUNTIF(Syn_Tiering!$Q$5:$Q$34,A35) -> 3 | C35: =B35/COUNTA(Syn_Tiering!$A$5:$A$34) -> 0.1 | D35: =Tier_Obligations!D5 -> 7 | E35: =Tier_Obligations!C5 -> P0
A36: =Config!B29 -> T1 - Critical | B36: =COUNTIF(Syn_Tiering!$Q$5:$Q$34,A36) -> 11 | C36: =B36/COUNTA(Syn_Tiering!$A$5:$A$34) -> 0.36666667 | D36: =Tier_Obligations!D6 -> 30 | E36: =Tier_Obligations!C6 -> P1
A37: =Config!B30 -> T2 - Elevated | B37: =COUNTIF(Syn_Tiering!$Q$5:$Q$34,A37) -> 11 | C37: =B37/COUNTA(Syn_Tiering!$A$5:$A$34) -> 0.36666667 | D37: =Tier_Obligations!D7 -> 60 | E37: =Tier_Obligations!C7 -> P2
A38: =Config!B31 -> T3 - Standard | B38: =COUNTIF(Syn_Tiering!$Q$5:$Q$34,A38) -> 5 | C38: =B38/COUNTA(Syn_Tiering!$A$5:$A$34) -> 0.16666667 | D38: =Tier_Obligations!D8 -> 120 | E38: =Tier_Obligations!C8 -> P3
A40: 3. Business unit × internal tier
A41: Business Unit | B41: =Config!B28 -> T0 - Stop | C41: =Config!B29 -> T1 - Critical | D41: =Config!B30 -> T2 - Elevated | E41: =Config!B31 -> T3 - Standard | F41: Total
A42: Retail Banking | B42: =COUNTIFS(Syn_AI_Inventory!$D$5:$D$34,$A42,Syn_Tiering!$Q$5:$Q$34,B$41) -> 0 | C42: =COUNTIFS(Syn_AI_Inventory!$D$5:$D$34,$A42,Syn_Tiering!$Q$5:$Q$34,C$41) -> 3 | D42: =COUNTIFS(Syn_AI_Inventory!$D$5:$D$34,$A42,Syn_Tiering!$Q$5:$Q$34,D$41) -> 4 | E42: =COUNTIFS(Syn_AI_Inventory!$D$5:$D$34,$A42,Syn_Tiering!$Q$5:$Q$34,E$41) -> 0 | F42: =SUM(B42:E42) -> 7
A43: Insurance | B43: =COUNTIFS(Syn_AI_Inventory!$D$5:$D$34,$A43,Syn_Tiering!$Q$5:$Q$34,B$41) -> 0 | C43: =COUNTIFS(Syn_AI_Inventory!$D$5:$D$34,$A43,Syn_Tiering!$Q$5:$Q$34,C$41) -> 2 | D43: =COUNTIFS(Syn_AI_Inventory!$D$5:$D$34,$A43,Syn_Tiering!$Q$5:$Q$34,D$41) -> 1 | E43: =COUNTIFS(Syn_AI_Inventory!$D$5:$D$34,$A43,Syn_Tiering!$Q$5:$Q$34,E$41) -> 0 | F43: =SUM(B43:E43) -> 3
A44: Human Resources | B44: =COUNTIFS(Syn_AI_Inventory!$D$5:$D$34,$A44,Syn_Tiering!$Q$5:$Q$34,B$41) -> 1 | C44: =COUNTIFS(Syn_AI_Inventory!$D$5:$D$34,$A44,Syn_Tiering!$Q$5:$Q$34,C$41) -> 3 | D44: =COUNTIFS(Syn_AI_Inventory!$D$5:$D$34,$A44,Syn_Tiering!$Q$5:$Q$34,D$41) -> 2 | E44: =COUNTIFS(Syn_AI_Inventory!$D$5:$D$34,$A44,Syn_Tiering!$Q$5:$Q$34,E$41) -> 0 | F44: =SUM(B44:E44) -> 6
...

Sheet AI_System_Register
A1: AI System Register – Classify Many Systems
A2: Fill in columns A–N (yellow). Columns O–Q are computed. Rows marked EXAMPLE are sample data - replace or delete.
A4: System ID | B4: System Name | C4: Description | D4: Owner | E4: Business Unit | F4: EU Nexus (Y/N) | G4: Art.5 Flag (Y/N) | H4: Annex I Safety Component (Y/N) | I4: Annex III Domain | J4: Profiling of Persons (Y/N) | K4: Art.6(3) Derogation Claimed (Y/N/N.A.) | L4: GPAI Model Provided (Y/N) | M4: Training Compute (FLOP) | N4: Interacts/Synthetic/Emotion Trigger (Y/N) | O4: EU AI Act Tier (computed) | P4: Internal Tier (computed) | Q4: Rationale (computed) | R4: Reviewed By | S4: Review Date | T4: Legal Sign-off (Y/N)
A5: AI-001 (EXAMPLE) | B5: Résumé Screening Tool | C5: Ranks and filters job applicants using résumé text | D5: A. Novak | E5: Human Resources | F5: Y | G5: N | H5: N | I5: Employment | J5: Y | K5: N | L5: N | N5: N | O5: =IF(A5="","",IF(F5="N","Out of EU AI Act Scope",IF(G5="Y","Prohibited (Art.5)",IF(H5="Y","High-Risk (Annex I)",IF(AND(I5<>"None",OR(J5="Y",K5="N")),"High-Risk (Annex III)",IF(L5="Y",IF(N(M5)>=[1]Config!$B$5,"GPAI with Systemic Risk","GPAI"),IF(N5="Y","Limited Risk (Art.50)","Minimal Risk"))))))) -> High-Risk (Annex III) | P5: =IF(O5="","",INDEX([1]Decision_Logic!$A$18:$A$21,MATCH(INDEX([1]Config!$B$9:$B$16,MATCH(O5,[1]Config!$A$9:$A$16,0)),{0;1;2;3},0))) -> T1 – Critical | Q5: =IF(A5="","",IF(F5="N","No EU nexus declared (Art.2).",IF(G5="Y","Art.5 prohibited practice indicated (Art.5) – escalate to Legal.",IF(H5="Y","Annex I safety component requiring conformity assessment (Art.6(1)).",IF(AND(I5<>"None",OR(J5="Y",K5="N")),"Annex III domain ('"&I5&"') with profiling and/or no valid derogation (Art.6(2)-(4)).",IF(L5="Y",IF(N(M5)>=[1]Config!$B$5,"GPAI above systemic-risk compute threshold (Art.51(2),55).","GPAI below systemic-risk threshold (Art.51-53)."),IF(N5="Y","Direct interaction / synthetic content / emotion or biometric trigger (Art.50).","No triggers identified."))))))) -> Annex III domain ('Employment') with profiling and/or no valid derogation (Art.6(2)-(4)).
A6: AI-002 (EXAMPLE) | B6: Customer Service Chatbot | C6: LLM assistant answering customer questions on the website | D6: C. Lindqvist | E6: Retail Banking | F6: Y | G6: N | H6: N | I6: None | J6: N | K6: N.A. | L6: N | N6: Y | O6: =IF(A6="","",IF(F6="N","Out of EU AI Act Scope",IF(G6="Y","Prohibited (Art.5)",IF(H6="Y","High-Risk (Annex I)",IF(AND(I6<>"None",OR(J6="Y",K6="N")),"High-Risk (Annex III)",IF(L6="Y",IF(N(M6)>=[1]Config!$B$5,"GPAI with Systemic Risk","GPAI"),IF(N6="Y","Limited Risk (Art.50)","Minimal Risk"))))))) -> Limited Risk (Art.50) | P6: =IF(O6="","",INDEX([1]Decision_Logic!$A$18:$A$21,MATCH(INDEX([1]Config!$B$9:$B$16,MATCH(O6,[1]Config!$A$9:$A$16,0)),{0;1;2;3},0))) -> T2 – Elevated | Q6: =IF(A6="","",IF(F6="N","No EU nexus declared (Art.2).",IF(G6="Y","Art.5 prohibited practice indicated (Art.5) – escalate to Legal.",IF(H6="Y","Annex I safety component requiring conformity assessment (Art.6(1)).",IF(AND(I6<>"None",OR(J6="Y",K6="N")),"Annex III domain ('"&I6&"') with profiling and/or no valid derogation (Art.6(2)-(4)).",IF(L6="Y",IF(N(M6)>=[1]Config!$B$5,"GPAI above systemic-risk compute threshold (Art.51(2),55).","GPAI below systemic-risk threshold (Art.51-53)."),IF(N6="Y","Direct interaction / synthetic content / emotion or biometric trigger (Art.50).","No triggers identified."))))))) -> Direct interaction / synthetic content / emotion or biometric trigger (Art.50).
A7: AI-003 (EXAMPLE) | B7: Card Fraud Detection Engine | C7: Real-time card transaction fraud scoring | D7: D. Okoye | E7: Retail Banking | F7: Y | G7: N | H7: N | I7: None | J7: N | K7: N.A. | L7: N | N7: N | O7: =IF(A7="","",IF(F7="N","Out of EU AI Act Scope",IF(G7="Y","Prohibited (Art.5)",IF(H7="Y","High-Risk (Annex I)",IF(AND(I7<>"None",OR(J7="Y",K7="N")),"High-Risk (Annex III)",IF(L7="Y",IF(N(M7)>=[1]Config!$B$5,"GPAI with Systemic Risk","GPAI"),IF(N7="Y","Limited Risk (Art.50)","Minimal Risk"))))))) -> Minimal Risk | P7: =IF(O7="","",INDEX([1]Decision_Logic!$A$18:$A$21,MATCH(INDEX([1]Config!$B$9:$B$16,MATCH(O7,[1]Config!$A$9:$A$16,0)),{0;1;2;3},0))) -> T3 – Standard | Q7: =IF(A7="","",IF(F7="N","No EU nexus declared (Art.2).",IF(G7="Y","Art.5 prohibited practice indicated (Art.5) – escalate to Legal.",IF(H7="Y","Annex I safety component requiring conformity assessment (Art.6(1)).",IF(AND(I7<>"None",OR(J7="Y",K7="N")),"Annex III domain ('"&I7&"') with profiling and/or no valid derogation (Art.6(2)-(4)).",IF(L7="Y",IF(N(M7)>=[1]Config!$B$5,"GPAI above systemic-risk compute threshold (Art.51(2),55).","GPAI below systemic-risk threshold (Art.51-53)."),IF(N7="Y","Direct interaction / synthetic content / emotion or biometric trigger (Art.50).","No triggers identified."))))))) -> No triggers identified.
O8: =IF(A8="","",IF(F8="N","Out of EU AI Act Scope",IF(G8="Y","Prohibited (Art.5)",IF(H8="Y","High-Risk (Annex I)",IF(AND(I8<>"None",OR(J8="Y",K8="N")),"High-Risk (Annex III)",IF(L8="Y",IF(N(M8)>=[1]Config!$B$5,"GPAI with Systemic Risk","GPAI"),IF(N8="Y","Limited Risk (Art.50)","Minimal Risk"))))))) | P8: =IF(O8="","",INDEX([1]Decision_Logic!$A$18:$A$21,MATCH(INDEX([1]Config!$B$9:$B$16,MATCH(O8,[1]Config!$A$9:$A$16,0)),{0;1;2;3},0))) | Q8: =IF(A8="","",IF(F8="N","No EU nexus declared (Art.2).",IF(G8="Y","Art.5 prohibited practice indicated (Art.5) – escalate to Legal.",IF(H8="Y","Annex I safety component requiring conformity assessment (Art.6(1)).",IF(AND(I8<>"None",OR(J8="Y",K8="N")),"Annex III domain ('"&I8&"') with profiling and/or no valid derogation (Art.6(2)-(4)).",IF(L8="Y",IF(N(M8)>=[1]Config!$B$5,"GPAI above systemic-risk compute threshold (Art.51(2),55).","GPAI below systemic-risk threshold (Art.51-53)."),IF(N8="Y","Direct interaction / synthetic content / emotion or biometric trigger (Art.50).","No triggers identified.")))))))
O9: =IF(A9="","",IF(F9="N","Out of EU AI Act Scope",IF(G9="Y","Prohibited (Art.5)",IF(H9="Y","High-Risk (Annex I)",IF(AND(I9<>"None",OR(J9="Y",K9="N")),"High-Risk (Annex III)",IF(L9="Y",IF(N(M9)>=[1]Config!$B$5,"GPAI with Systemic Risk","GPAI"),IF(N9="Y","Limited Risk (Art.50)","Minimal Risk"))))))) | P9: =IF(O9="","",INDEX([1]Decision_Logic!$A$18:$A$21,MATCH(INDEX([1]Config!$B$9:$B$16,MATCH(O9,[1]Config!$A$9:$A$16,0)),{0;1;2;3},0))) | Q9: =IF(A9="","",IF(F9="N","No EU nexus declared (Art.2).",IF(G9="Y","Art.5 prohibited practice indicated (Art.5) – escalate to Legal.",IF(H9="Y","Annex I safety component requiring conformity assessment (Art.6(1)).",IF(AND(I9<>"None",OR(J9="Y",K9="N")),"Annex III domain ('"&I9&"') with profiling and/or no valid derogation (Art.6(2)-(4)).",IF(L9="Y",IF(N(M9)>=[1]Config!$B$5,"GPAI above systemic-risk compute threshold (Art.51(2),55).","GPAI below systemic-risk threshold (Art.51-53)."),IF(N9="Y","Direct interaction / synthetic content / emotion or biometric trigger (Art.50).","No triggers identified.")))))))
O10: =IF(A10="","",IF(F10="N","Out of EU AI Act Scope",IF(G10="Y","Prohibited (Art.5)",IF(H10="Y","High-Risk (Annex I)",IF(AND(I10<>"None",OR(J10="Y",K10="N")),"High-Risk (Annex III)",IF(L10="Y",IF(N(M10)>=[1]Config!$B$5,"GPAI with Systemic Risk","GPAI"),IF(N10="Y","Limited Risk (Art.50)","Minimal Risk"))))))) | P10: =IF(O10="","",INDEX([1]Decision_Logic!$A$18:$A$21,MATCH(INDEX([1]Config!$B$9:$B$16,MATCH(O10,[1]Config!$A$9:$A$16,0)),{0;1;2;3},0))) | Q10: =IF(A10="","",IF(F10="N","No EU nexus declared (Art.2).",IF(G10="Y","Art.5 prohibited practice indicated (Art.5) – escalate to Legal.",IF(H10="Y","Annex I safety component requiring conformity assessment (Art.6(1)).",IF(AND(I10<>"None",OR(J10="Y",K10="N")),"Annex III domain ('"&I10&"') with profiling and/or no valid derogation (Art.6(2)-(4)).",IF(L10="Y",IF(N(M10)>=[1]Config!$B$5,"GPAI above systemic-risk compute threshold (Art.51(2),55).","GPAI below systemic-risk threshold (Art.51-53)."),IF(N10="Y","Direct interaction / synthetic content / emotion or biometric trigger (Art.50).","No triggers identified.")))))))
O11: =IF(A11="","",IF(F11="N","Out of EU AI Act Scope",IF(G11="Y","Prohibited (Art.5)",IF(H11="Y","High-Risk (Annex I)",IF(AND(I11<>"None",OR(J11="Y",K11="N")),"High-Risk (Annex III)",IF(L11="Y",IF(N(M11)>=[1]Config!$B$5,"GPAI with Systemic Risk","GPAI"),IF(N11="Y","Limited Risk (Art.50)","Minimal Risk"))))))) | P11: =IF(O11="","",INDEX([1]Decision_Logic!$A$18:$A$21,MATCH(INDEX([1]Config!$B$9:$B$16,MATCH(O11,[1]Config!$A$9:$A$16,0)),{0;1;2;3},0))) | Q11: =IF(A11="","",IF(F11="N","No EU nexus declared (Art.2).",IF(G11="Y","Art.5 prohibited practice indicated (Art.5) – escalate to Legal.",IF(H11="Y","Annex I safety component requiring conformity assessment (Art.6(1)).",IF(AND(I11<>"None",OR(J11="Y",K11="N")),"Annex III domain ('"&I11&"') with profiling and/or no valid derogation (Art.6(2)-(4)).",IF(L11="Y",IF(N(M11)>=[1]Config!$B$5,"GPAI above systemic-risk compute threshold (Art.51(2),55).","GPAI below systemic-risk threshold (Art.51-53)."),IF(N11="Y","Direct interaction / synthetic content / emotion or biometric trigger (Art.50).","No triggers identified.")))))))
O12: =IF(A12="","",IF(F12="N","Out of EU AI Act Scope",IF(G12="Y","Prohibited (Art.5)",IF(H12="Y","High-Risk (Annex I)",IF(AND(I12<>"None",OR(J12="Y",K12="N")),"High-Risk (Annex III)",IF(L12="Y",IF(N(M12)>=[1]Config!$B$5,"GPAI with Systemic Risk","GPAI"),IF(N12="Y","Limited Risk (Art.50)","Minimal Risk"))))))) | P12: =IF(O12="","",INDEX([1]Decision_Logic!$A$18:$A$21,MATCH(INDEX([1]Config!$B$9:$B$16,MATCH(O12,[1]Config!$A$9:$A$16,0)),{0;1;2;3},0))) | Q12: =IF(A12="","",IF(F12="N","No EU nexus declared (Art.2).",IF(G12="Y","Art.5 prohibited practice indicated (Art.5) – escalate to Legal.",IF(H12="Y","Annex I safety component requiring conformity assessment (Art.6(1)).",IF(AND(I12<>"None",OR(J12="Y",K12="N")),"Annex III domain ('"&I12&"') with profiling and/or no valid derogation (Art.6(2)-(4)).",IF(L12="Y",IF(N(M12)>=[1]Config!$B$5,"GPAI above systemic-risk compute threshold (Art.51(2),55).","GPAI below systemic-risk threshold (Art.51-53)."),IF(N12="Y","Direct interaction / synthetic content / emotion or biometric trigger (Art.50).","No triggers identified.")))))))
O13: =IF(A13="","",IF(F13="N","Out of EU AI Act Scope",IF(G13="Y","Prohibited (Art.5)",IF(H13="Y","High-Risk (Annex I)",IF(AND(I13<>"None",OR(J13="Y",K13="N")),"High-Risk (Annex III)",IF(L13="Y",IF(N(M13)>=[1]Config!$B$5,"GPAI with Systemic Risk","GPAI"),IF(N13="Y","Limited Risk (Art.50)","Minimal Risk"))))))) | P13: =IF(O13="","",INDEX([1]Decision_Logic!$A$18:$A$21,MATCH(INDEX([1]Config!$B$9:$B$16,MATCH(O13,[1]Config!$A$9:$A$16,0)),{0;1;2;3},0))) | Q13: =IF(A13="","",IF(F13="N","No EU nexus declared (Art.2).",IF(G13="Y","Art.5 prohibited practice indicated (Art.5) – escalate to Legal.",IF(H13="Y","Annex I safety component requiring conformity assessment (Art.6(1)).",IF(AND(I13<>"None",OR(J13="Y",K13="N")),"Annex III domain ('"&I13&"') with profiling and/or no valid derogation (Art.6(2)-(4)).",IF(L13="Y",IF(N(M13)>=[1]Config!$B$5,"GPAI above systemic-risk compute threshold (Art.51(2),55).","GPAI below systemic-risk threshold (Art.51-53)."),IF(N13="Y","Direct interaction / synthetic content / emotion or biometric trigger (Art.50).","No triggers identified.")))))))
O14: =IF(A14="","",IF(F14="N","Out of EU AI Act Scope",IF(G14="Y","Prohibited (Art.5)",IF(H14="Y","High-Risk (Annex I)",IF(AND(I14<>"None",OR(J14="Y",K14="N")),"High-Risk (Annex III)",IF(L14="Y",IF(N(M14)>=[1]Config!$B$5,"GPAI with Systemic Risk","GPAI"),IF(N14="Y","Limited Risk (Art.50)","Minimal Risk"))))))) | P14: =IF(O14="","",INDEX([1]Decision_Logic!$A$18:$A$21,MATCH(INDEX([1]Config!$B$9:$B$16,MATCH(O14,[1]Config!$A$9:$A$16,0)),{0;1;2;3},0))) | Q14: =IF(A14="","",IF(F14="N","No EU nexus declared (Art.2).",IF(G14="Y","Art.5 prohibited practice indicated (Art.5) – escalate to Legal.",IF(H14="Y","Annex I safety component requiring conformity assessment (Art.6(1)).",IF(AND(I14<>"None",OR(J14="Y",K14="N")),"Annex III domain ('"&I14&"') with profiling and/or no valid derogation (Art.6(2)-(4)).",IF(L14="Y",IF(N(M14)>=[1]Config!$B$5,"GPAI above systemic-risk compute threshold (Art.51(2),55).","GPAI below systemic-risk threshold (Art.51-53)."),IF(N14="Y","Direct interaction / synthetic content / emotion or biometric trigger (Art.50).","No triggers identified.")))))))
O15: =IF(A15="","",IF(F15="N","Out of EU AI Act Scope",IF(G15="Y","Prohibited (Art.5)",IF(H15="Y","High-Risk (Annex I)",IF(AND(I15<>"None",OR(J15="Y",K15="N")),"High-Risk (Annex III)",IF(L15="Y",IF(N(M15)>=[1]Config!$B$5,"GPAI with Systemic Risk","GPAI"),IF(N15="Y","Limited Risk (Art.50)","Minimal Risk"))))))) | P15: =IF(O15="","",INDEX([1]Decision_Logic!$A$18:$A$21,MATCH(INDEX([1]Config!$B$9:$B$16,MATCH(O15,[1]Config!$A$9:$A$16,0)),{0;1;2;3},0))) | Q15: =IF(A15="","",IF(F15="N","No EU nexus declared (Art.2).",IF(G15="Y","Art.5 prohibited practice indicated (Art.5) – escalate to Legal.",IF(H15="Y","Annex I safety component requiring conformity assessment (Art.6(1)).",IF(AND(I15<>"None",OR(J15="Y",K15="N")),"Annex III domain ('"&I15&"') with profiling and/or no valid derogation (Art.6(2)-(4)).",IF(L15="Y",IF(N(M15)>=[1]Config!$B$5,"GPAI above systemic-risk compute threshold (Art.51(2),55).","GPAI below systemic-risk threshold (Art.51-53)."),IF(N15="Y","Direct interaction / synthetic content / emotion or biometric trigger (Art.50).","No triggers identified.")))))))
O16: =IF(A16="","",IF(F16="N","Out of EU AI Act Scope",IF(G16="Y","Prohibited (Art.5)",IF(H16="Y","High-Risk (Annex I)",IF(AND(I16<>"None",OR(J16="Y",K16="N")),"High-Risk (Annex III)",IF(L16="Y",IF(N(M16)>=[1]Config!$B$5,"GPAI with Systemic Risk","GPAI"),IF(N16="Y","Limited Risk (Art.50)","Minimal Risk"))))))) | P16: =IF(O16="","",INDEX([1]Decision_Logic!$A$18:$A$21,MATCH(INDEX([1]Config!$B$9:$B$16,MATCH(O16,[1]Config!$A$9:$A$16,0)),{0;1;2;3},0))) | Q16: =IF(A16="","",IF(F16="N","No EU nexus declared (Art.2).",IF(G16="Y","Art.5 prohibited practice indicated (Art.5) – escalate to Legal.",IF(H16="Y","Annex I safety component requiring conformity assessment (Art.6(1)).",IF(AND(I16<>"None",OR(J16="Y",K16="N")),"Annex III domain ('"&I16&"') with profiling and/or no valid derogation (Art.6(2)-(4)).",IF(L16="Y",IF(N(M16)>=[1]Config!$B$5,"GPAI above systemic-risk compute threshold (Art.51(2),55).","GPAI below systemic-risk threshold (Art.51-53)."),IF(N16="Y","Direct interaction / synthetic content / emotion or biometric trigger (Art.50).","No triggers identified.")))))))
O17: =IF(A17="","",IF(F17="N","Out of EU AI Act Scope",IF(G17="Y","Prohibited (Art.5)",IF(H17="Y","High-Risk (Annex I)",IF(AND(I17<>"None",OR(J17="Y",K17="N")),"High-Risk (Annex III)",IF(L17="Y",IF(N(M17)>=[1]Config!$B$5,"GPAI with Systemic Risk","GPAI"),IF(N17="Y","Limited Risk (Art.50)","Minimal Risk"))))))) | P17: =IF(O17="","",INDEX([1]Decision_Logic!$A$18:$A$21,MATCH(INDEX([1]Config!$B$9:$B$16,MATCH(O17,[1]Config!$A$9:$A$16,0)),{0;1;2;3},0))) | Q17: =IF(A17="","",IF(F17="N","No EU nexus declared (Art.2).",IF(G17="Y","Art.5 prohibited practice indicated (Art.5) – escalate to Legal.",IF(H17="Y","Annex I safety component requiring conformity assessment (Art.6(1)).",IF(AND(I17<>"None",OR(J17="Y",K17="N")),"Annex III domain ('"&I17&"') with profiling and/or no valid derogation (Art.6(2)-(4)).",IF(L17="Y",IF(N(M17)>=[1]Config!$B$5,"GPAI above systemic-risk compute threshold (Art.51(2),55).","GPAI below systemic-risk threshold (Art.51-53)."),IF(N17="Y","Direct interaction / synthetic content / emotion or biometric trigger (Art.50).","No triggers identified.")))))))
O18: =IF(A18="","",IF(F18="N","Out of EU AI Act Scope",IF(G18="Y","Prohibited (Art.5)",IF(H18="Y","High-Risk (Annex I)",IF(AND(I18<>"None",OR(J18="Y",K18="N")),"High-Risk (Annex III)",IF(L18="Y",IF(N(M18)>=[1]Config!$B$5,"GPAI with Systemic Risk","GPAI"),IF(N18="Y","Limited Risk (Art.50)","Minimal Risk"))))))) | P18: =IF(O18="","",INDEX([1]Decision_Logic!$A$18:$A$21,MATCH(INDEX([1]Config!$B$9:$B$16,MATCH(O18,[1]Config!$A$9:$A$16,0)),{0;1;2;3},0))) | Q18: =IF(A18="","",IF(F18="N","No EU nexus declared (Art.2).",IF(G18="Y","Art.5 prohibited practice indicated (Art.5) – escalate to Legal.",IF(H18="Y","Annex I safety component requiring conformity assessment (Art.6(1)).",IF(AND(I18<>"None",OR(J18="Y",K18="N")),"Annex III domain ('"&I18&"') with profiling and/or no valid derogation (Art.6(2)-(4)).",IF(L18="Y",IF(N(M18)>=[1]Config!$B$5,"GPAI above systemic-risk compute threshold (Art.51(2),55).","GPAI below systemic-risk threshold (Art.51-53)."),IF(N18="Y","Direct interaction / synthetic content / emotion or biometric trigger (Art.50).","No triggers identified.")))))))
O19: =IF(A19="","",IF(F19="N","Out of EU AI Act Scope",IF(G19="Y","Prohibited (Art.5)",IF(H19="Y","High-Risk (Annex I)",IF(AND(I19<>"None",OR(J19="Y",K19="N")),"High-Risk (Annex III)",IF(L19="Y",IF(N(M19)>=[1]Config!$B$5,"GPAI with Systemic Risk","GPAI"),IF(N19="Y","Limited Risk (Art.50)","Minimal Risk"))))))) | P19: =IF(O19="","",INDEX([1]Decision_Logic!$A$18:$A$21,MATCH(INDEX([1]Config!$B$9:$B$16,MATCH(O19,[1]Config!$A$9:$A$16,0)),{0;1;2;3},0))) | Q19: =IF(A19="","",IF(F19="N","No EU nexus declared (Art.2).",IF(G19="Y","Art.5 prohibited practice indicated (Art.5) – escalate to Legal.",IF(H19="Y","Annex I safety component requiring conformity assessment (Art.6(1)).",IF(AND(I19<>"None",OR(J19="Y",K19="N")),"Annex III domain ('"&I19&"') with profiling and/or no valid derogation (Art.6(2)-(4)).",IF(L19="Y",IF(N(M19)>=[1]Config!$B$5,"GPAI above systemic-risk compute threshold (Art.51(2),55).","GPAI below systemic-risk threshold (Art.51-53)."),IF(N19="Y","Direct interaction / synthetic content / emotion or biometric trigger (Art.50).","No triggers identified.")))))))
... O29: =IF(A29="","",IF(F29="N","Out of EU AI Act Scope",IF(G29="Y","Prohibited (Art.5)",IF(H29="Y","High-Risk (Annex I)",IF(AND(I29<>"None",OR(J29="Y",K29="N")),"High-Risk (Annex III)",IF(L29="Y",IF(N(M29)>=[1]Config!$B$5,"GPAI with Systemic Risk","GPAI"),IF(N29="Y","Limited Risk (Art.50)","Minimal Risk"))))))) | P29: =IF(O29="","",INDEX([1]Decision_Logic!$A$18:$A$21,MATCH(INDEX([1]Config!$B$9:$B$16,MATCH(O29,[1]Config!$A$9:$A$16,0)),{0;1;2;3},0))) | Q29: =IF(A29="","",IF(F29="N","No EU nexus declared (Art.2).",IF(G29="Y","Art.5 prohibited practice indicated (Art.5) – escalate to Legal.",IF(H29="Y","Annex I safety component requiring conformity assessment (Art.6(1)).",IF(AND(I29<>"None",OR(J29="Y",K29="N")),"Annex III domain ('"&I29&"') with profiling and/or no valid derogation (Art.6(2)-(4)).",IF(L29="Y",IF(N(M29)>=[1]Config!$B$5,"GPAI above systemic-risk compute threshold (Art.51(2),55).","GPAI below systemic-risk threshold (Art.51-53)."),IF(N29="Y","Direct interaction / synthetic content / emotion or biometric trigger (Art.50).","No triggers identified.")))))))

Sheet Annex_III_Guide
A1: Annex III – High-Risk Use-Case Domains (Art. 6(2))
A2: Use this to answer the domain question in R4 of Decision_Logic.
A4: # | B4: Domain | C4: Typical High-Risk Use Cases (Art. 6(2), Annex III) | D4: Exclusions / Notes
A5: 1 | B5: Biometrics | C5: Remote biometric identification; biometric categorisation inferring sensitive attributes; emotion recognition | D5: Biometric verification whose sole purpose is confirming a person's identity ('is this the same person?') is excluded; several biometric uses are outright prohibited under Art.5
A6: 2 | B6: Critical infrastructure | C6: AI safety components in the management/operation of critical digital infrastructure, road traffic, or the supply of water, gas, heating or electricity | D6: Cybersecurity tools alone are not automatically in scope
A7: 3 | B7: Education & vocational training | C7: Determining access/admission; evaluating learning outcomes; assessing the appropriate level of education; monitoring/detecting prohibited student behaviour during tests | D7: Emotion recognition in an educational setting is prohibited outright (Art.5)
A8: 4 | B8: Employment, workers' management & access to self-employment | C8: Recruitment (targeted job ads, filtering/evaluating applications); decisions on promotion, termination, task allocation based on behaviour or traits; monitoring/evaluating performance | D8: Emotion recognition in the workplace is prohibited outright (Art.5)
A9: 5 | B9: Essential private & public services | C9: Eligibility for public assistance/benefits; creditworthiness assessment / credit scoring; risk assessment and pricing for life and health insurance; evaluating and classifying emergency calls, and dispatch/prioritisation of emergency services | D9: AI used purely to detect financial fraud is excluded from the credit-scoring category
A10: 6 | B10: Law enforcement | C10: Assessing risk of a person offending or reoffending or of becoming a victim; polygraph-type tools; evaluating the reliability of evidence; profiling in the course of investigation or prosecution | D10: Several law-enforcement biometric uses are prohibited outright (Art.5)
A11: 7 | B11: Migration, asylum & border control | C11: Risk or security assessment of migrants/applicants; examining eligibility of applications for asylum, visa or residence; detection, recognition or identification of persons in this context | D11: Purely administrative or travel-document verification tasks are more limited in scope
A12: 8 | B12: Administration of justice & democratic processes | C12: AI systems assisting a judicial authority in researching/interpreting facts and applying the law; AI used to influence the outcome of an election or referendum, or voting behaviour | D12: Purely administrative back-office case-management tools are generally excluded

Sheet Decision_Logic
A1: EU AI Act - Risk Tiering Decision Logic (evaluated in order)
A2: This ordered logic is implemented as formulas in Quick_Classifier and AI_System_Register.
A4: Rule | B4: Order | C4: Question | D4: If YES | E4: If NO | F4: Legal Basis | G4: Notes
A5: R1 | B5: 1 | C5: Is the system placed on the EU market, put into service in the EU, or is its output used within the EU? | D5: Continue to R2 | E5: STOP → 'Out of EU AI Act Scope' (internal governance only) | F5: Art. 2 | G5: Non-EU-only systems can still be governed internally, but the AI Act does not apply.
A6: R2 | B6: 2 | C6: Does the system perform a practice prohibited under Art.5? e.g. subliminal/manipulative techniques causing harm; exploiting vulnerabilities (age, disability, socio-economic situation); social scoring; predictive policing based solely on profiling; untargeted scraping of facial images; emotion recognition in the workplace or education; biometric categorisation inferring sensitive attributes (race, political opinions, sexual orientation, etc.); real-time remote biometric identification in public spaces for law enforcement (narrow exceptions only); non-consensual intimate-image / CSAM generation (added by the Digital Omnibus) | D6: STOP → 'Prohibited (Art.5)' – do not place on market / withdraw | E6: Continue to R3 | F6: Art. 5 (as amended by Reg. (EU) 2026/1744) | G6: Read the free-text description carefully – prohibited uses are often not obvious from a checkbox (e.g. an 'interview scoring tool' that infers emotion). Highest penalty tier: up to €35m or 7% of global turnover.
A7: R3 | B7: 3 | C7: Is the system a safety component of, or is it itself, a product covered by the Annex I list of EU product-safety legislation (e.g. machinery, toys, lifts, medical devices, aviation) requiring third-party conformity assessment? | D7: 'High-Risk (Annex I)' | E7: Continue to R4 | F7: Art. 6(1), Annex I | G7: Application deferred to 2 Aug 2028 by the Digital Omnibus.
A8: R4 | B8: 4 | C8: Is the intended purpose in one of the 8 Annex III domains? (see Annex_III_Guide) – biometrics; critical infrastructure; education; employment; essential private/public services; law enforcement; migration/border/asylum; administration of justice or democratic processes | D8: Continue to R5 | E8: Continue to R6 (skip to GPAI check) | F8: Art. 6(2), Annex III
A9: R5 | B9: 5 | C9: Within that Annex III domain: does the system profile natural persons (per Art.4(4) GDPR-style profiling), OR is a valid Art.6(3) narrow-procedural-task derogation NOT claimed/documented? | D9: 'High-Risk (Annex III)' | E9: Continue to R6 – but the derogation must be formally assessed and documented, and the system registered (Art.49(2)) | F9: Art. 6(2)–(4) | G9: Profiling always overrides the derogation. Reviewer should challenge weak derogation claims.
A10: R6 | B10: 6 | C10: Does your organisation provide a general-purpose AI model (a foundation/base model usable for a wide range of tasks, not fine-tuned end-use only)? | D10: Continue to R7 | E10: Continue to R8 | F10: Art. 51–53 | G10: Deployers who only use a vendor's GPAI model (without providing one) are not GPAI providers themselves.
A11: R7 | B11: 7 | C11: Was the model trained with cumulative compute ≥ 10^25 FLOP (see Config), or has the Commission designated it as posing systemic risk? | D11: 'GPAI with Systemic Risk' | E11: 'GPAI' | F11: Art. 51(2), Art. 55 | G11: Systemic-risk providers must notify the Commission within 2 weeks of meeting the criterion.
A12: R8 | B12: 8 | C12: Does the system interact directly with natural persons, generate synthetic audio/image/video/text, or perform emotion recognition / biometric categorisation (and is not already Prohibited or High-Risk)? | D12: 'Limited Risk (Art.50)' | E12: Continue to R9 | F12: Art. 50 | G12: Transparency duties can also apply on top of a High-Risk tier – track this separately if relevant.
A13: R9 | B13: 9 | C13: None of the above triggers apply. | D13: — | E13: 'Minimal Risk' | F13: — | G13: Voluntary codes of conduct and AI-literacy obligations (Art.4) still apply.
A16: Reference: internal severity tiers (for prioritisation once the EU category is known)
A17: Suggested Internal Tier | B17: EU AI Act Categories Mapped | C17: Typical Review Depth
A18: T0 – Stop | B18: Prohibited (Art.5) | C18: Immediate legal determination; cease/withdraw
A19: T1 – Critical | B19: High-Risk (Annex I or III); GPAI with Systemic Risk | C19: Full assessment against all applicable obligations; senior sign-off
A20: T2 – Elevated | B20: Limited Risk (Art.50) | C20: Targeted assessment of transparency/documentation duties
A21: T3 – Standard | B21: Minimal Risk; Out of EU AI Act Scope | C21: Baseline governance and periodic attestation

Sheet MVP_Roadmap
A1: MVP Roadmap – Agentic AI Risk Tiering Prototype
A2: Four incremental MVPs; each delivers standalone value and de-risks the next.
A4: Attribute | B4: MVP-1: Inventory & Intake | C4: MVP-2: EU AI Act Risk Tiering | D4: MVP-3: Framework Crosswalk & Gap Assessment | E4: MVP-4: Remediation, Monitoring & Reporting
A5: Objective | B5: Build a trusted, continuously refreshed inventory of AI systems with complete intake data – this is the prerequisite for risk-tiering. | C5: Automatically classify every inventoried system into an EU AI Act category and an internal risk tier, with explainable reasoning and human validation. | D5: Map each tier to obligations across EU AI Act, NIST AI RMF and ISO/IEC 42001; collect evidence and assess control gaps per system. | E5: Close the loop: remediation planning, continuous monitoring, re-tiering triggers, incident triage and governance reporting.
A6: Business problem solved | B6: Shadow AI, spreadsheet inventories, inconsistent owner-provided data; no single source of truth. | C6: Manual, slow and inconsistent risk classification; prohibited/high-risk uses discovered late. | D6: Fragmented compliance effort across three frameworks; duplicated evidence requests; unclear priorities. | E6: Findings without follow-through; tier goes stale after model/vendor/use-case changes; slow board reporting.
A7: In scope | B7: Discovery of AI systems (procurement, cloud, SaaS, code repos); conversational intake; canonical record schema; completeness scoring; owner/role assignment (provider vs deployer); audit log. | C7: Rules engine (R1–R10); LLM reasoning over free-text; RAG over AI Act; reconcile rules vs LLM; confidence-based review routing; reviewer workbench; contextual score overlay; prohibited-practice stop; golden test set. | D7: Versioned crosswalk (24 requirements); tier→obligation applicability; evidence collection from GRC/MLOps/doc stores; gap status + compliance score; NIST profile and ISO SoA draft; GPAI checklist. | E7: Remediation plans with SLA by tier; action tracker; monitoring ingest; re-tiering triggers; Art.73 incident triage; regulatory watch; dashboards & board pack; agent performance monitoring.
A8: Out of scope | B8: Tiering decisions; control assessment; automated blocking of systems. | C8: Full conformity assessment; technical model testing (bias/robustness execution); other jurisdictions. | D8: Automated remediation execution; certification audit; vendor due-diligence workflows. | E8: Multi-jurisdiction extension (e.g., US state laws); automated regulator submissions; model-level red-teaming.
A9: Agents involved | B9: A0 Orchestrator, A1 Discovery, A2 Intake & Enrichment | C9: A0 Orchestrator, A3 Regulatory Knowledge (RAG), A4 Risk Tiering, A5 Tier Review & Challenge | D9: A6 Framework Mapping, A7 Evidence Collection, A8 Gap Assessment | E9: A9 Remediation Planning, A10 Monitoring & Re-tiering, A11 Incident Triage, A12 Governance Reporting
A10: Key inputs / data | B10: Procurement & cloud-spend exports, SaaS/SSO logs, code-repo scan, model cards, owner questionnaires. | C10: Inventory records (Syn_AI_Inventory), AI Act text & guidelines, Tiering_Rules, labelled golden set. | D10: Framework_Map, policies, model documentation, test reports, DPIAs, vendor contracts, MLOps registry. | E10: Gap results, action log, monitoring telemetry, incident tickets, regulatory feeds, approver matrix.
A11: Key outputs | B11: AI inventory with completeness score; shadow-AI findings; owner assignments. | C11: EU tier + internal tier + rationale + confidence + citations; reviewed decisions; prohibited-practice alerts. | D11: Applicable requirement set per system; evidence links; gap status; compliance score; NIST/ISO artefacts. | E11: Remediation plan; monitoring alerts; re-tier decisions; incident triage record; board/committee packs.
A12: Framework alignment | B12: EU: Art.6/49 (classification, registration prep), Art.4. NIST: GOVERN 1.6 (inventory). ISO 42001: 4.3, A.4.2. | C12: EU: Art.5, 6, Annex I/III, Art.50, 51–52. NIST: MAP 1.1, MAP 1.5, MAP 5.1. ISO 42001: 6.1.2, 6.1.4, A.5.2. | D12: EU: Art.9–15, 17, 26, 27, 53, 55. NIST: GOVERN/MAP/MEASURE subcategories per Framework_Map. ISO 42001: 8.x, Annex A. | E12: EU: Art.72, 73. NIST: MANAGE 1–4. ISO 42001: 9.1–9.3, 10.1–10.2, A.6.2.6, A.8.4.
A13: Acceptance criteria | B13: ≥90% of seeded shadow-AI test systems detected; ≥95% of mandatory intake fields complete for in-scope systems; every record versioned and attributable to an owner. | C13: Agent–SME agreement ≥90% on golden set; 100% of prohibited cases escalated (no misses); every decision carries article citations; reviewer override captured with reason. | D13: ≥85% requirement-level status matches SME judgement on sample; each evidence link traceable; crosswalk versioned with change history. | E13: ≥95% material change events trigger re-tier review within SLA; remediation plans accepted with ≤30% edits; reports reconcile 100% to source data.
A14: Success KPIs (targets) | B14: Inventory coverage ≥90% of known AI; intake completeness ≥95%; time-to-register ≤5 days. | C14: Tiering cycle time ≤2 days (fast-track ≤1 day); override rate ≤15%; prohibited-practice recall 100%. | D14: Requirements auto-assessed ≥70%; evidence request duplication -50%; compliance score visible for 100% T0–T2. | E14: Overdue actions ≤10%; MTTR for re-tier ≤5 days; board pack prep time -70%.
A15: Human-in-the-loop design | B15: System owner confirms extracted answers; governance analyst approves new shadow-AI records. | C15: Single reviewer for fast-track (confidence ≥ threshold, agent = rules); two reviewers + Legal for T0/T1 or disagreement; T0 hard-stop needs Legal sign-off. | D15: Control owners attest evidence; 2nd line challenges 'Implemented' claims on T1 systems. | E15: Action owners approve plans; independent validator confirms closure; CRO/Committee approves risk acceptance.
... A22: Demo scenario | B22: Shadow-AI scan surfaces 'Store Camera Demographic Analytics (pilot)'; owner completes intake via chat. | C22: Video Interview Analyser: rules say High-Risk, agent flags Art.5 emotion recognition, Legal confirms Prohibited (see AI-028). | D22: Retail Credit Scoring Model: 20 requirements applied; gaps found in data governance and human oversight. | E22: Vendor update on Credit Limit Recommender triggers re-tier and creates P2 remediation actions.

Sheet MVP_Backlog
A1: MVP Backlog – User Stories
A2: Effort points are relative estimates (Fibonacci-like). MoSCoW priority.
A4: Story ID | B4: MVP | C4: Epic | D4: User Story | E4: Priority | F4: Effort (pts) | G4: Acceptance Criteria | H4: Agent | I4: Framework Reference
A5: US-101 | B5: MVP-1 | C5: Discovery | D5: As an AI governance lead, I want the Discovery Agent to scan procurement, cloud spend, SaaS/SSO logs and code repos so that shadow AI is surfaced. | E5: Must | F5: 8 | G5: ≥90% of seeded shadow-AI systems detected; each finding links to source evidence | H5: A1 Discovery | I5: NIST GOVERN 1.6; ISO A.4.2
A6: US-102 | B6: MVP-1 | C6: Inventory | D6: As a governance analyst, I want a canonical AI system record (27 fields incl. tiering flags) so that data is consistent. | E6: Must | F6: 5 | G6: Schema approved; validation rules block invalid values | H6: A2 Intake | I6: EU Art.6; ISO 4.3
A7: US-103 | B7: MVP-1 | C7: Intake | D7: As a system owner, I want to complete intake via conversational chat with pre-filled answers from my documents so that effort is minimal. | E7: Must | F7: 8 | G7: ≥60% fields pre-filled; owner confirms each extracted answer | H7: A2 Intake | I7: NIST MAP 1.1
A8: US-104 | B8: MVP-1 | C8: Intake | D8: As a governance analyst, I want completeness scoring and automated nudges so that records reach ≥95% completeness. | E8: Should | F8: 3 | G8: Score visible per record; reminders escalate after 5 days | H8: A2 Intake | I8: ISO 7.5
A9: US-105 | B9: MVP-1 | C9: Inventory | D9: As an auditor, I want immutable version history of every record change so that decisions are traceable. | E9: Must | F9: 5 | G9: Every edit stores who/when/what; export available | H9: A0 Orchestrator | I9: EU Art.12 (logging principle); ISO 7.5
A10: US-106 | B10: MVP-1 | C10: Intake | D10: As Legal, I want the provider/deployer role determined per system so that correct obligations apply. | E10: Must | F10: 5 | G10: Role captured with rationale; changes trigger re-tier flag | H10: A2 Intake | I10: EU Art.3, Art.25
A11: US-107 | B11: MVP-1 | C11: Security | D11: As a CISO, I want PII/secret redaction before any LLM call so that sensitive data is protected. | E11: Must | F11: 3 | G11: 0 unredacted PII in prompt logs on test set | H11: A0 Orchestrator | I11: ISO A.7.x; NIST GOVERN 1.x
A12: US-108 | B12: MVP-1 | C12: Platform | D12: As a platform owner, I want an orchestrator with run logging so that every agent action is auditable. | E12: Must | F12: 5 | G12: Run ID, agent, version, inputs/outputs hash logged | H12: A0 Orchestrator | I12: ISO 9.1; EU Art.12
A13: US-201 | B13: MVP-2 | C13: Knowledge | D13: As a tiering agent, I want a RAG index of AI Act articles, annexes, Omnibus amendments and guidelines so that citations are grounded. | E13: Must | F13: 8 | G13: Answers cite retrievable passages; citation accuracy ≥95% | H13: A3 Regulatory Knowledge | I13: EU Art.5,6,50,51–55
A14: US-202 | B14: MVP-2 | C14: Rules | D14: As a compliance lead, I want a deterministic rules engine implementing R1–R10 so that baseline tiering is reproducible. | E14: Must | F14: 8 | G14: 100% match with Legal-approved test table | H14: A4 Risk Tiering | I14: EU Art.5,6,Annex I/III
A15: US-203 | B15: MVP-2 | C15: LLM reasoning | D15: As a reviewer, I want the LLM to read free-text descriptions and detect Art.5/Annex III indicators missed by intake flags so that hidden risks are caught. | E15: Must | F15: 13 | G15: Catches ≥90% of seeded hidden-indicator cases | H15: A4 Risk Tiering | I15: EU Art.5,6(2),6(3)
A16: US-204 | B16: MVP-2 | C16: Rules | D16: As a reviewer, I want rules-vs-LLM disagreements automatically escalated so that conflicts are never silently resolved. | E16: Must | F16: 5 | G16: 100% disagreements routed to full review | H16: A4/A5 | I16: NIST MAP 5.1
... A43: US-412 | B43: MVP-2 | C43: Governance | D43: As an AI ethics lead, I want a periodic sample audit of fast-track decisions. | E43: Should | F43: 3 | G43: 10% monthly sample reviewed | H43: A5 Review | I43: ISO 9.2

Sheet Agent_Catalog
A1: Agent Catalog
A2: 13 agents across four MVPs; autonomy: Low = human decides, Medium = agent proposes/human approves, High = agent acts within guardrails.
A4: Agent ID | B4: Agent | C4: MVP | D4: Purpose | E4: Key Inputs | F4: Key Outputs | G4: Tools / Integrations | H4: Reasoning Approach | I4: Autonomy Level | J4: Human Checkpoint | K4: Guardrails | L4: Evaluation Metrics | M4: Synthetic Data Sheet
A5: A0 | B5: Orchestrator / Supervisor | C5: MVP-1+ | D5: Plans work, routes tasks to agents, manages state, retries, review routing and audit logging | E5: Inventory events, agent outputs, Config | F5: Task graph, run log, routing decisions | G5: Workflow engine, state store, message bus | H5: Deterministic state machine with LLM planning for exceptions | I5: High (routing only) | J5: None for routing; humans approve all classifications | K5: No agent can approve its own output; PII redaction before LLM calls; run IDs immutable | L5: Task success rate; retry rate; latency | M5: Syn_Agent_Run_Log
A6: A1 | B6: AI Discovery Agent | C6: MVP-1 | D6: Finds unregistered AI/ML use (shadow AI) from procurement, cloud spend, SaaS/SSO logs, code repositories | E6: Procurement export, cloud billing, SSO/app catalogue, repo scan | F6: Candidate AI systems with evidence links | G6: Connectors/APIs, entity resolution, signature library (AI SDKs, model endpoints) | H6: Rules + LLM classification of vendor/app descriptions | I6: Medium | J6: Governance analyst approves new records | K6: Read-only access; evidence link mandatory; no data content ingestion | L6: Recall of seeded shadow AI; precision | M6: Syn_AI_Inventory (Discovery Source)
A7: A2 | B7: Intake & Enrichment Agent | C7: MVP-1 | D7: Conducts conversational intake; pre-fills from model cards/docs; scores completeness; nudges owners | E7: Owner chat, model cards, architecture docs | F7: Complete inventory record, completeness %, open questions | G7: Chat UI, document parser, vector store | H7: LLM extraction to JSON schema with source spans | I7: Medium | J7: System owner confirms every extracted value | K7: Schema validation; show source for each pre-filled value; no silent overwrites | L7: Field accuracy; pre-fill rate; completion time | M7: Syn_AI_Inventory
A8: A3 | B8: Regulatory Knowledge Agent (RAG) | C8: MVP-2 | D8: Retrieves and cites AI Act provisions, Omnibus amendments, guidelines, NIST/ISO texts (licensed/owned) | E8: Query from A4/A5/A6 | F8: Passages with citations and version/date | G8: Vector index, document store, citation verifier | H8: Retrieval-augmented generation; citation-only answers | I8: High (read-only) | J8: Legal curates corpus and approves updates | K8: Answers only from indexed corpus; verify quotes exist; show effective dates | L8: Citation accuracy; retrieval recall | M8: Reg_Timeline; Tiering_Rules
A9: A4 | B9: Risk Tiering Agent | C9: MVP-2 | D9: Assigns EU AI Act category + internal tier using rules engine and LLM reading of free text; explains | E9: Inventory record, Tiering_Rules, RAG passages | F9: EU tier, internal tier, rationale, confidence, citations | G9: Rules engine, LLM (structured output), RAG | H9: Hybrid: deterministic rules first, LLM second-opinion; disagreements escalate | I9: Medium (proposes) | J9: Reviewer approves/overrides; T0/T1 need two approvals + Legal | K9: Prohibited indicators always escalate; low confidence → full review; explanations must cite | L9: Agent–SME agreement; prohibited recall; override rate | M9: Syn_Tiering
A10: A5 | B10: Tier Review & Challenge Agent | C10: MVP-2 | D10: Independent critic: argues the opposite classification, checks derogation claims (Art.6(3)), looks for missed Annex III/Art.5 signals | E10: Tiering output, inventory record | F10: Challenge notes, disagreement flag | G10: LLM (separate prompt/model), RAG | H10: Adversarial second opinion | I10: Medium | J10: Reviewer sees both views | K10: Cannot change tier; results shown to reviewer | L10: Disagreement usefulness (accepted %) | M10: Syn_Tiering (Agent vs SME)
A11: A6 | B11: Framework Mapping Agent | C11: MVP-3 | D11: Applies crosswalk: derives applicable EU/NIST/ISO requirements per tier; generates NIST profile & ISO SoA draft | E11: Final tier, Framework_Map | F11: Applicable requirement list per system | G11: Crosswalk data store, templating | H11: Deterministic lookup + LLM drafting | I11: High (lookup) / Medium (drafts) | J11: Compliance approves crosswalk versions | K11: Versioned crosswalk; drafts marked AI-generated | L11: Applicability accuracy | M11: Framework_Map
A12: A7 | B12: Evidence Collection Agent | C12: MVP-3 | D12: Collects and links evidence artefacts (policies, model cards, test reports, DPIAs, logs, contracts) | E12: Requirement list, repositories | F12: Evidence links with hash/timestamp | G12: GRC, MLOps registry, document stores, email/ticket search | H12: Search + LLM relevance ranking | I12: Medium | J12: Control owner confirms relevance | K12: Least-privilege access; store references not content; freshness checks | L12: Evidence coverage; relevance precision | M12: Syn_Gap_Assessment (Evidence Ref)
A13: A8 | B13: Gap Assessment Agent | C13: MVP-3 | D13: Judges evidence vs each requirement; assigns status + confidence; computes compliance credit | E13: Requirement, evidence | F13: Status (Implemented/Partial/Not/NA), rationale, confidence | G13: LLM document QA, scoring service | H13: Rubric-based judgement with citations to evidence | I13: Medium | J13: 2nd line challenges; T1 'Implemented' needs attestation | K13: No 'Implemented' without evidence; low confidence → human | L13: Agreement with SME; false-positive 'Implemented' | M13: Syn_Gap_Assessment
A14: A9 | B14: Remediation Planning Agent | C14: MVP-4 | D14: Proposes actions, owners, priority, due dates from tier SLA and gap type; tracks and escalates | E14: Gaps, Tier_Obligations, capacity | F14: Remediation plan, reminders, escalations | G14: Ticketing (Jira/ServiceNow), calendar | H14: Playbook lookup + LLM specialisation of action text | I14: Medium | J14: Owner accepts; validator closes; risk acceptance human-only | K14: Cannot close own actions; SLA per tier | L14: % accepted unedited; on-time closure | M14: Syn_Remediation
A15: A10 | B15: Monitoring & Re-tiering Agent | C15: MVP-4 | D15: Watches drift/bias/incidents/vendor and intended-purpose changes; triggers re-tiering | E15: Monitoring telemetry, change logs, vendor notices | F15: Alerts, re-tier requests | G15: Event bus, MLOps monitors, change management | H15: Threshold rules + LLM summarisation | I15: High (alerts) / Medium (re-tier request) | J15: Governance lead decides re-tier | K15: Dedup; severity thresholds; evidence attached | L15: Trigger recall; false-alert rate | M15: Syn_Monitoring
... A17: A12 | B17: Governance Reporting Agent | C17: MVP-4 | D17: Builds dashboards, board packs, agent-performance reports | E17: All approved outputs | F17: Dashboards, narrative, KPI trends | G17: BI tool, document generator | H17: Templated narrative from computed metrics with citations | I17: High (draft) / Low (publish) | J17: Head of AI Governance approves before distribution | K17: Numbers only from computed sources; reconcile check | L17: Report accuracy; prep time | M17: Dashboard

Sheet Tiering_Rules
A1: Risk Tiering Decision Logic (evaluated in order)
A2: Implemented as formulas in Syn_Tiering (R1–R12). LLM agents (A4/A5) test the same logic against free-text descriptions.
A4: Rule ID | B4: Order | C4: Step | D4: Question / Condition | E4: Intake Fields Used | F4: Outcome | G4: Legal Basis | H4: Notes / Edge Cases
A5: R1 | B5: 1 | C5: Scope | D5: Is the system placed on the EU market, put into service in the EU, or is its output used in the EU? | E5: EU Nexus | F5: N → 'Out of EU AI Act Scope' (apply internal tier only) | G5: Art. 2 | H5: Non-EU-only use still receives NIST/ISO internal governance; re-check if use extends to EU.
A6: R2 | B6: 2 | C6: Prohibited practices | D6: Does the system perform any Art.5 prohibited practice? (subliminal/manipulative techniques; exploiting vulnerabilities; social scoring; predictive policing based solely on profiling; untargeted facial-image scraping; emotion recognition in workplace/education; biometric categorisation inferring sensitive attributes; real-time remote biometric ID in public for law enforcement (narrow exceptions); plus new Omnibus additions on non-consensual intimate imagery / CSAM generation) | E6: Art.5 Flag; LLM reading of Description | F6: Y → 'Prohibited (Art.5)' → T0 Stop | G6: Art. 5 (as amended by Reg. (EU) 2026/1744) | H6: LLM agent must check description even when flag = N (e.g., interview emotion analysis). Legal must confirm. Highest fine tier (up to €35m or 7% turnover).
A7: R3 | B7: 3 | C7: Product safety | D7: Is the AI a safety component of (or itself) a product covered by Annex I Union harmonisation legislation requiring third-party conformity assessment? | E7: Annex I Safety Component | F7: Y → 'High-Risk (Annex I)' | G7: Art. 6(1), Annex I | H7: Application date deferred to 2 Aug 2028 by Omnibus.
A8: R4 | B8: 4 | C8: Annex III use case | D8: Is the intended use in an Annex III domain (biometrics, critical infrastructure, education, employment, essential services, law enforcement, migration, justice/democracy)? | E8: Annex III Domain | F8: Domain ≠ None → candidate High-Risk | G8: Art. 6(2), Annex III | H8: See domain guide below. Exclusions: fraud detection (not credit scoring), biometric verification-only.
A9: R5 | B9: 5 | C9: Profiling override | D9: Does the Annex III system profile natural persons? | E9: Profiling of Persons | F9: Y → 'High-Risk (Annex III)' (no derogation) | G9: Art. 6(3) last subparagraph | H9: Profiling always high-risk when in Annex III domain.
A10: R6 | B10: 6 | C10: Derogation | D10: If not profiling: does Art.6(3) apply (narrow procedural task, improves prior human activity, detects deviations without replacing human assessment, or preparatory task) and is it documented? | E10: Art 6(3) Derogation Claimed | F10: Derogation = Y & profiling = N → not High-Risk (continue R7–R10); else 'High-Risk (Annex III)' | G10: Art. 6(3), 6(4) | H10: Provider must document the assessment and register the system (Art.49(2)); reviewer must challenge weak claims (A5).
A11: R7 | B11: 7 | C11: GPAI model | D11: Does the organisation provide a general-purpose AI model? | E11: GPAI Provided | F11: Y → 'GPAI' (continue R8) | G11: Art. 51–53 | H11: Model provider obligations since 2 Aug 2025; deployers using vendor GPAI are typically not GPAI providers.
A12: R8 | B12: 8 | C12: Systemic risk | D12: Training compute ≥ 10^25 FLOP (presumption) or Commission designation? | E12: Training Compute (FLOP) | F12: ≥ threshold → 'GPAI with Systemic Risk' | G12: Art. 51(2), Art. 55 | H12: Threshold in Config; notify Commission within 2 weeks of meeting criterion.
A13: R9 | B13: 9 | C13: Transparency | D13: Does the system interact directly with persons, generate synthetic audio/image/video/text, or perform emotion recognition/biometric categorisation? | E13: Interacts; Generates Synthetic Content; Emotion/Biometric | F13: Any Y → 'Limited Risk (Art.50)' | G13: Art. 50 | H13: Art.50 duties can also apply on top of High-Risk (flag shown separately). Art.50(2) marking for legacy systems from 2 Dec 2026.
A14: R10 | B14: 10 | C14: Default | D14: None of the above | E14: — | F14: 'Minimal Risk' | G14: — | H14: Voluntary codes of conduct; AI literacy and internal governance still apply.
A15: R11 | B15: 11 | C15: Contextual score | D15: Internal score = w1·Impact + w2·Data sensitivity + w3·Scale + w4·Autonomy (weights in Config) | E15: Impact Severity; Data Sensitivity; Scale; Autonomy | F15: Score ≥ 4.0 → T1; ≥ 3.0 → T2; else T3 | G15: NIST AI RMF MAP 1.5, MAP 5.1; ISO 42001 6.1.2 | H15: Captures risks outside the EU categories (e.g., non-EU credit pre-screening, voice biometrics).
A16: R12 | B16: 12 | C16: Final internal tier | D16: Final tier = most severe of EU-derived tier and score-derived tier; Prohibited always T0 | E16: Outputs of R2–R11 | F16: T0 Stop / T1 Critical / T2 Elevated / T3 Standard | G16: Org policy (see Tier_Obligations) | H16: Reviewer may raise but not lower a tier without documented rationale.
A19: Annex III domain guide (Art. 6(2))
A20: # | B20: Domain | C20: Typical high-risk use cases | D20: Exclusions / notes
A21: 1 | B21: Biometrics | C21: Remote biometric identification; biometric categorisation by sensitive attributes; emotion recognition | D21: Biometric verification whose sole purpose is confirming a person's identity is excluded; some uses are prohibited under Art.5
A22: 2 | B22: Critical infrastructure | C22: Safety components in management/operation of critical digital infrastructure, road traffic, supply of water, gas, heating, electricity | D22: Cybersecurity-only tools are not automatically in scope
A23: 3 | B23: Education & vocational training | C23: Admission/access; evaluating learning outcomes; assessing appropriate education level; monitoring prohibited behaviour during tests | D23: Emotion recognition in education is prohibited (Art.5)
A24: 4 | B24: Employment & workers management | C24: Recruitment/selection (targeted job ads, filtering, evaluating candidates); decisions on terms, promotion, termination; task allocation based on behaviour/traits; performance monitoring | D24: Emotion recognition in the workplace is prohibited (Art.5)
A25: 5 | B25: Essential private & public services | C25: Eligibility for public benefits; creditworthiness / credit scoring; risk assessment & pricing for life and health insurance; emergency call evaluation, dispatch and triage | D25: AI used to detect financial fraud is excluded from the credit-scoring category
A26: 6 | B26: Law enforcement | C26: Risk of victimisation/offending assessment; polygraph-type tools; evidence reliability; profiling in investigations | D26: Some uses prohibited (Art.5)
A27: 7 | B27: Migration, asylum & border control | C27: Risk assessment of migrants; examination of applications; detection/identification of persons | D27: Travel-document verification is limited
A28: 8 | B28: Administration of justice & democratic processes | C28: AI assisting judicial authorities in researching/interpreting facts and law; influencing elections/voting behaviour | D28: Purely administrative back-office tools excluded

Sheet Tier_Obligations
A1: Internal Tier Definitions & EU AI Act Obligations
